<?xml version="1.0"?>

<robot
  name="avant_fork" xmlns:xacro="http://ros.org/wiki/xacro">

  <!-- Materials a.k.a. used colors in the model -->
  
  <material name="green">
     <color rgba="0 .48 0 1"/>
  </material>

  <material name="black">
    <color rgba=".15 .15 .15 1"/>
  </material>

  <material name="white">
     <color rgba="1 1 1 1"/>
  </material>

  <material name="gray">
     <color rgba=".4 .4 .4 1"/>
  </material>

  <material name="yellow">
     <color rgba="1 1 0 1"/>
  </material>


<!-- The first link. Named avant to locate the part in the same position
     as the published coordinate system from the actual model. -->  
  
  <link
    name="avant">
    <visual>
      <origin
        xyz="0.0 0.0 0.0"
        rpy="0 0 0" />
      <geometry>
        <cylinder length="0.01" radius="0.01"/>
      </geometry>
      <material name="green"/>
    </visual>
  </link>

<!-- Frontbody and middle cylinder. Frontbody is connected to middle cylinder
     with a fixed joint. ( Middle cylinder's origin is -0.6m (x-direction) 
	 and 0.0866m (z-direction) from frontbody's origin, which is at the center
	 of the front axle.) The first link avant has the origin at its center
     and is then connected to the origin of the frontbody. Thereby the origin
     of the whole robot is at the center of the front axle	 --> 
 
  <link
   name="front_body">
    <visual>
      <origin
        xyz="0.0 0.0 0.0"
        rpy="0 0 0" />
      <geometry>
        <mesh
         filename="package://avant_description/meshes/Frontbody.STL"/>
      </geometry>
      <material name="green"/>
    </visual>
  </link>

  <joint name="avant_to_front" type="fixed">
    <parent link="avant"/>
    <child link="front_body"/>
    <origin xyz="0.0 0.0 0.0"/>
  </joint>


  <link
    name="middle_cylinder">
    <visual>
      <origin
        xyz="0.0 0.0 0.0"
        rpy="0 0 0" />
      <geometry>
        <cylinder length="0.29" radius="0.0275"/>
      </geometry>
      <material name="gray"/>
    </visual>
  </link>

  <joint name="front_to_center" type="fixed">
    <parent link="front_body"/>
    <child link="middle_cylinder"/>
    <origin xyz="-0.6 0.0 0.0866"/>
  </joint>

<!-- Back frame and back body. Back frame is connected to middle cylinder
     with a revolute joint. ( Back frame's origin is -0.6m (x-direction) 
	 and -0.0866m (z-direction) from cylinder's origin.) Backbody is then
	 connected with a fixed joint to back frame, origin at the same spot
	 as back frame's one. -->
	 
  <link
    name="back_frame">
    <visual>
     <origin
       xyz="-0.6 0.0 -0.0866"
       rpy="0 0 0" />
     <geometry>
       <mesh
         filename="package://avant_description/meshes/Backframe.STL"/>
     </geometry>
     <material name="gray"/>
    </visual>
  </link>

  <joint name="center_link" type="revolute">
    <parent link="middle_cylinder"/>
    <child link="back_frame"/>
    <axis xyz="0 0 1"/>
    <origin xyz="0.0 0.0 0.0"/>
    <limit
      lower="-1.75"
      upper="1.75"
      effort="1000"
      velocity="1" />
  </joint>

  <link
   name="back_body">
    <visual>
      <origin
        xyz="0.0 0.0 0.0"
        rpy="0 0 0" />
      <geometry>
        <mesh
         filename="package://avant_description/meshes/Backbody.STL"/>
      </geometry>
      <material name="green"/>
    </visual>
  </link>

  <joint name="back_frame_to_back_body" type="fixed">
    <parent link="back_frame"/>
    <child link="back_body"/>
    <origin xyz="-0.6 0.0 -0.0866"/>
  </joint>

<!-- Boom, where the front boom is connected, linked to front body 
     origin with a revolute joint. The distance from the front body 
     origin to boom origin is in x-direction -0.6m
                              in y-direction -0.257m and
        	              in z-direction 0.95m.-->
	 
  <link
    name="boom">
    <visual>
     <origin
       xyz="0.0 0.0 0.0"
       rpy="0 0 0" />
     <geometry>
       <mesh
         filename="package://avant_description/meshes/Boom.STL"/>
     </geometry>
     <material name="green"/>
    </visual>
  </link>

  <joint name="boom_angle" type="revolute">
    <parent link="front_body"/>
    <child link="boom"/>
    <axis xyz="0 -1 0"/>
    <origin xyz="-0.6 -0.257 0.95"/>
    <limit
      lower="-1.75"
      upper="1.75"
      effort="1000"
      velocity="1" />
  </joint>

<!-- Front boom, where the tool fixture is connected, linked to boom 
     origin with a prismatic joint. The distance from the boom origin
     to front boom origin (in y-direction) is 0.106m.-->

 <link
    name="front_boom">
    <visual>
     <origin
       xyz="-1.193 0.0 0.0"
       rpy="0 0 0" />
     <geometry>
       <mesh
         filename="package://avant_description/meshes/Front_boom.STL"/>
     </geometry>
     <material name="green"/>
    </visual>
  </link>

  <joint name="telescope_length" type="prismatic">
    <parent link="boom"/>
    <child link="front_boom"/>
    <axis xyz="1 0 0"/>
    <origin xyz="0.0 0.106 0.0"/>
    <limit
      lower="0"
      upper="2"
      effort="1000"
      velocity="1" />
  </joint>

<!-- Tool fixture, where the tool is connected, linked to front boom 
     origin with a revolute joint. The distance from the center of
     front boom to center of tool (in y-direction) is 0.151m.-->

 <link
    name="tool_fixture">
    <visual>
     <origin
       xyz="0.0 0.0 0.0"
       rpy="0 0 0" />
     <geometry>
       <mesh
         filename="package://avant_description/meshes/Tool_fixture.STL"/>
     </geometry>
     <material name="green"/>
    </visual>
  </link>

  <joint name="fork_angle" type="revolute">
    <parent link="front_boom"/>
    <child link="tool_fixture"/>
    <axis xyz="0 -1 0"/>
    <origin xyz="0.0 0.151 0.0"/>
    <limit
      lower="-1"
      upper="1"
      effort="1000"
      velocity="1" />
  </joint>

<!-- Tool being used (in this case, fork), linked to tool fixture 
     origin with a fixed joint. The distance from fork angle joint
     to tool origin is 0.07m (in x-direction).-->

 <link
    name="fork">
    <visual>
     <origin
       xyz="0.0 0.0 0.0"
       rpy="0 0 0" />
     <geometry>
       <mesh
         filename="package://avant_description/meshes/Trukkipiikit.STL"/>
     </geometry>
     <material name="black"/>
    </visual>
  </link>

  <joint name="tool_joint" type="fixed">
    <parent link="tool_fixture"/>
    <child link="fork"/>
    <origin xyz="0.07 0.0 0.0"/>
  </joint>

<!-- Seat, linked to front body origin with a fixed joint -->

  <link
   name="seat">
    <visual>
      <origin
        xyz="0.0 0.0 0.0"
        rpy="0 0 0" />
      <geometry>
        <mesh
         filename="package://avant_description/meshes/Seat.STL"/>
      </geometry>
      <material name="gray"/>
    </visual>
  </link>

  <joint name="seat_to_front_body" type="fixed">
    <parent link="front_body"/>
    <child link="seat"/>
    <origin xyz="0.0 0.0 0.0"/>
  </joint>

<!-- Safety frame, linked to front body origin with a fixed joint -->

  <link
   name="safety_frame">
    <visual>
      <origin
        xyz="0.0 0.0 0.0"
        rpy="0 0 0" />
      <geometry>
        <mesh
         filename="package://avant_description/meshes/Safety_frame.STL"/>
      </geometry>
      <material name="black"/>
    </visual>
  </link>

  <joint name="frame_to_front_body" type="fixed">
    <parent link="front_body"/>
    <child link="safety_frame"/>
    <origin xyz="0.0 0.0 0.0"/>
  </joint>
 
<!-- Scanner fixture, linked to front body origin with a fixed joint -->

  <link
   name="scanner_fixture">
    <visual>
      <origin
        xyz="0.0 0.0 0.0"
        rpy="0 0 0" />
      <geometry>
        <mesh
         filename="package://avant_description/meshes/Kattoskanneri_kiinnitys.STL"/>
      </geometry>
      <material name="black"/>
    </visual>
  </link>

  <joint name="scan_fixture" type="fixed">
    <parent link="front_body"/>
    <child link="scanner_fixture"/>
    <origin xyz="0.0 0.0 0.0"/>
  </joint>

<!-- Scanner parts, linked to front body origin with a fixed joint -->

  <link
   name="scanner_gray">
    <visual>
      <origin
        xyz="0.0 0.0 0.0"
        rpy="0 0 0" />
      <geometry>
        <mesh
         filename="package://avant_description/meshes/Skanneri_harmaaosa.STL"/>
      </geometry>
      <material name="gray"/>
    </visual>
  </link>

  <joint name="scanner" type="fixed">
    <parent link="front_body"/>
    <child link="scanner_gray"/>
    <origin xyz="0.0 0.0 0.0"/>
  </joint>

  <link
   name="scanner_black">
    <visual>
      <origin
        xyz="0.0 0.0 0.0"
        rpy="0 0 0" />
      <geometry>
        <mesh
         filename="package://avant_description/meshes/Skanneri_mustaosa.STL"/>
      </geometry>
      <material name="black"/>
    </visual>
  </link>

  <joint name="scanner_bl" type="fixed">
    <parent link="front_body"/>
    <child link="scanner_black"/>
    <origin xyz="0.0 0.0 0.0"/>
  </joint>

<!-- Pole on the roof, linked to front body origin with a fixed joint -->

  <link
   name="pole_yellow">
    <visual>
      <origin
        xyz="0.0 0.0 0.0"
        rpy="0 0 0" />
      <geometry>
        <mesh
         filename="package://avant_description/meshes/Kattotolppa_keltainen.STL"/>
      </geometry>
      <material name="yellow"/>
    </visual>
  </link>

  <joint name="pole_1" type="fixed">
    <parent link="front_body"/>
    <child link="pole_yellow"/>
    <origin xyz="0.0 0.0 0.0"/>
  </joint>
 
<!-- Pole on the roof, linked to front body origin with a fixed joint -->

  <link
   name="pole_black">
    <visual>
      <origin
        xyz="0.0 0.0 0.0"
        rpy="0 0 0" />
      <geometry>
        <mesh
         filename="package://avant_description/meshes/Kattotolppa_musta.STL"/>
      </geometry>
      <material name="black"/>
    </visual>
  </link>

  <joint name="pole_2" type="fixed">
    <parent link="front_body"/>
    <child link="pole_black"/>
    <origin xyz="0.0 0.0 0.0"/>
  </joint>

<!-- Pole on the roof, linked to front body origin with a fixed joint -->

  <link
   name="pole_white">
    <visual>
      <origin
        xyz="0.0 0.0 0.0"
        rpy="0 0 0" />
      <geometry>
        <mesh
         filename="package://avant_description/meshes/Kattotolppa_valkoinen.STL"/>
      </geometry>
      <material name="white"/>
    </visual>
  </link>

  <joint name="pole_3" type="fixed">
    <parent link="front_body"/>
    <child link="pole_white"/>
    <origin xyz="0.0 0.0 0.0"/>
  </joint>
  
<!-- Box on the roof, linked to front body origin with a fixed joint -->

 <link
   name="roof">
    <visual>
      <origin
        xyz="0.0 0.0 0.0"
        rpy="0 0 0" />
      <geometry>
        <mesh
         filename="package://avant_description/meshes/Katto.STL"/>
      </geometry>
      <material name="black"/>
    </visual>
  </link>

  <joint name="roof_to_front_body" type="fixed">
    <parent link="front_body"/>
    <child link="roof"/>
    <origin xyz="0.0 0.0 0.0"/>
  </joint>

<!-- Ligths and fans on the side, linked to front body origin with a fixed
     joint -->

 <link
   name="headlight_right">
    <visual>
      <origin
        xyz="0.0 0.0 0.0"
        rpy="0 0 0" />
      <geometry>
        <mesh
         filename="package://avant_description/meshes/Valo_oikea.STL"/>
      </geometry>
      <material name="yellow"/>
    </visual>
  </link>

  <joint name="headlight_1" type="fixed">
    <parent link="front_body"/>
    <child link="headlight_right"/>
    <origin xyz="0.0 0.0 0.0"/>
  </joint>

 <link
   name="headlight_left">
    <visual>
      <origin
        xyz="0.0 0.0 0.0"
        rpy="0 0 0" />
      <geometry>
        <mesh
         filename="package://avant_description/meshes/Valo_vasen.STL"/>
      </geometry>
      <material name="yellow"/>
    </visual>
  </link>

  <joint name="headlight_2" type="fixed">
    <parent link="front_body"/>
    <child link="headlight_left"/>
    <origin xyz="0.0 0.0 0.0"/>
  </joint>
    
 <link
   name="cooling_fan_front">
    <visual>
      <origin
        xyz="0.0 0.0 0.0"
        rpy="0 0 0" />
      <geometry>
        <mesh
         filename="package://avant_description/meshes/Puhallin_etu.STL"/>
      </geometry>
      <material name="gray"/>
    </visual>
  </link>

  <joint name="fan_front" type="fixed">
    <parent link="front_body"/>
    <child link="cooling_fan_front"/>
    <origin xyz="0.0 0.0 0.0"/>
  </joint>

 <link
   name="cooling_fan_rear">
    <visual>
      <origin
        xyz="0.0 0.0 0.0"
        rpy="0 0 0" />
      <geometry>
        <mesh
         filename="package://avant_description/meshes/Puhallin_taka.STL"/>
      </geometry>
      <material name="gray"/>
    </visual>
  </link>

  <joint name="fan_rear" type="fixed">
    <parent link="front_body"/>
    <child link="cooling_fan_rear"/>
    <origin xyz="0.0 0.0 0.0"/>
  </joint>

 <!-- Rims, wheels and center pins. Continuous joints between
      body and rim, fixed joints between wheels, rims and pins--> 
  
  <link
    name="back_right_rim">
    <visual>
      <origin
        xyz="0 0 0"
        rpy="0 0 0" />
      <geometry>
        <mesh
         filename="package://avant_description/meshes/Vanne.STL"/>
      </geometry>
     <material name="gray"/>
    </visual>
  </link>

  <joint name="back_right_rim_joint" type="fixed">
    <parent link="back_body"/>
    <child link="back_right_rim"/>
    <origin xyz="0.0 -0.4827 0.0" rpy="0 0 0"/>
  </joint>
  
 <link
    name="back_right_wheel">
    <visual>
      <origin
        xyz="0 0 0"
        rpy="0 0 0" />
      <geometry>
        <mesh
         filename="package://avant_description/meshes/Rengas.STL"/>
      </geometry>
      <material name="black"/>
    </visual>
  </link>

  <joint name="back_right_wheel_joint" type="fixed">
    <parent link="back_right_rim"/>
    <child link="back_right_wheel"/>
    <origin xyz="0.0 0.0 0.0" rpy="0 0 0"/>
  </joint>
 
 <link
    name="back_right_pin">
    <visual>
      <origin
        xyz="0 0 0"
        rpy="0 0 0" />
      <geometry>
        <mesh
         filename="package://avant_description/meshes/Rengas_keskitappi.STL"/>
      </geometry>
      <material name="gray"/>
    </visual>
  </link>

  <joint name="back_right_pin_joint" type="fixed">
    <parent link="back_right_rim"/>
    <child link="back_right_pin"/>
    <origin xyz="0.0 0.0 0.0" rpy="0 0 0"/>
  </joint>
  
  <link
    name="back_left_rim">
    <visual>
      <origin
        xyz="0 0 0"
        rpy="0 0 3.14159" />
      <geometry>
        <mesh
         filename="package://avant_description/meshes/Vanne.STL"/>
      </geometry>
      <material name="gray"/>
    </visual>
  </link>

  <joint name="back_left_rim_joint" type="fixed">
    <parent link="back_body"/>
    <child link="back_left_rim"/>
    <origin xyz="0.0 0.4827 0.0" rpy="0 0 0"/>
  </joint>
 
 <link
    name="back_left_wheel">
    <visual>
      <origin
        xyz="0 0 0"
        rpy="0 0 3.14159" />
      <geometry>
        <mesh
         filename="package://avant_description/meshes/Rengas.STL"/>
      </geometry>
      <material name="black"/>
    </visual>
  </link>

  <joint name="back_left_wheel_joint" type="fixed">
    <parent link="back_left_rim"/>
    <child link="back_left_wheel"/>
    <origin xyz="0.0 0.0 0.0" rpy="0 0 0"/>
  </joint>
 
 <link
    name="back_left_pin">
    <visual>
      <origin
        xyz="0 0 0"
        rpy="0 0 3.14159" />
      <geometry>
        <mesh
         filename="package://avant_description/meshes/Rengas_keskitappi.STL"/>
      </geometry>
      <material name="gray"/>
    </visual>
  </link>

  <joint name="back_left_pin_joint" type="fixed">
    <parent link="back_left_rim"/>
    <child link="back_left_pin"/>
    <origin xyz="0.0 0.0 0.0" rpy="0 0 0"/>
  </joint>
  
  <link
    name="front_right_rim">
    <visual>
      <origin
        xyz="0 0 0"
        rpy="0 0 0" />
      <geometry>
        <mesh
         filename="package://avant_description/meshes/Vanne.STL"/>
      </geometry>
      <material name="gray"/>
    </visual>
  </link>

  <joint name="front_right_rim_joint" type="fixed">
    <parent link="front_body"/>
    <child link="front_right_rim"/>
    <origin xyz="0.0 -0.4827 0.0" rpy="0 0 0"/>
  </joint>
 
 <link
    name="front_right_wheel">
    <visual>
      <origin
        xyz="0 0 0"
        rpy="0 0 0" />
      <geometry>
        <mesh
         filename="package://avant_description/meshes/Rengas.STL"/>
      </geometry>
      <material name="black"/>
    </visual>
  </link>

  <joint name="front_right_wheel_joint" type="fixed">
    <parent link="front_right_rim"/>
    <child link="front_right_wheel"/>
    <origin xyz="0.0 0.0 0.0" rpy="0 0 0"/>
  </joint>
 
 <link
    name="front_right_pin">
    <visual>
      <origin
        xyz="0 0 0"
        rpy="0 0 0" />
      <geometry>
        <mesh
         filename="package://avant_description/meshes/Rengas_keskitappi.STL"/>
      </geometry>
      <material name="gray"/>
    </visual>
  </link>

  <joint name="front_right_pin_joint" type="fixed">
    <parent link="front_right_rim"/>
    <child link="front_right_pin"/>
    <origin xyz="0.0 0.0 0.0" rpy="0 0 0"/>
  </joint>

  <link
    name="front_left_rim">
    <visual>
      <origin
        xyz="0 0 0"
        rpy="0 0 3.14159" />
      <geometry>
        <mesh
         filename="package://avant_description/meshes/Vanne.STL"/>
      </geometry>
      <material name="gray"/>
    </visual>
  </link>

  <joint name="front_left_rim_joint" type="fixed">
    <parent link="front_body"/>
    <child link="front_left_rim"/>
    <origin xyz="0.0 0.4827 0.0" rpy="0 0 0"/>
  </joint>
 
 <link
    name="front_left_wheel">
    <visual>
      <origin
        xyz="0 0 0"
        rpy="0 0 3.14159" />
      <geometry>
        <mesh
         filename="package://avant_description/meshes/Rengas.STL"/>
      </geometry>
      <material name="black"/>
    </visual>
  </link>

  <joint name="front_left_wheel_joint" type="fixed">
    <parent link="front_left_rim"/>
    <child link="front_left_wheel"/>
    <origin xyz="0.0 0.0 0.0" rpy="0 0 0"/>
  </joint>
 
 <link
    name="front_left_pin">
    <visual>
      <origin
        xyz="0 0 0"
        rpy="0 0 3.14159" />
      <geometry>
        <mesh
         filename="package://avant_description/meshes/Rengas_keskitappi.STL"/>
      </geometry>
      <material name="gray"/>
    </visual>
  </link>

  <joint name="front_left_pin_joint" type="fixed">
    <parent link="front_left_rim"/>
    <child link="front_left_pin"/>
    <origin xyz="0.0 0.0 0.0" rpy="0 0 0"/>
  </joint>

</robot>
